Workbook

Sheet 📋 Instructions
A1: BSS/OSS LM Studio Development Master Tracker
A2: Version 1.0 | Strategy: Zero-Flaw TDD with 12GB GPU
A4: HOW TO USE THIS WORKBOOK
A6: Sheet | B6: Purpose | C6: When to use
A7: 📋 Instructions | B7: This sheet — legend, column guide, workflow rules | C7: Read first, keep open
A8: 🔧 Environment Setup | B8: One-time machine setup tasks before writing any code | C8: Day 0
A9: 🗄️ DB Migrations | B9: All 15 goose migration sessions, one table per session | C9: Week 1-2
A10: 🔐 Crypto Module | B10: AES-GCM-256 PII encryption — zero-dependency module | C10: Week 3
A11: 📡 RADIUS AAA | B11: Worker pool, auth, dedup, FUP, observability | C11: Week 4-5
A12: 💳 Billing Module | B12: GST, wallet, dunning, GSTR-1, invoice PDF | C12: Week 6-7
A13: 🔔 Notifications | B13: WhatsApp/SMS/Email dispatcher, DND, delivery log | C13: Week 8
A14: ⚡ FUP + Asynq | B14: FUP scanner, CoA/PoD tasks, dead-letter monitor | C14: Week 9
A15: 🔑 API + Auth | B15: JWT middleware, RBAC, subscriber health endpoint | C15: Week 10
A16: 📊 Revenue + Franchise | B16: Reconciliation, forecast, LCO commission | C16: Week 11
A17: 🌐 Portal | B17: Subscriber self-service web portal | C17: Week 12
... A20: 📎 Prompt Snippets | B20: Reusable context blocks to paste into LM Studio | C20: Every session
A22: COLUMN GUIDE — main task sheets
A24: Column | B24: Meaning | C24: Notes
A25: Session ID | B25: Unique identifier for each LM Studio chat session | C25: Format: MOD-NNN (e.g. DB-001, AAA-003)
A26: Phase / Week | B26: Which development week this belongs to | C26: Follow in order — later phases depend on earlier ones
A27: Task Title | B27: What this session produces | C27: One function or one file per session
A28: FR IDs | B28: Which requirements this satisfies | C28: Trace back to SRS Doc 02
A29: Doc Reference | B29: Which DDS/DBD/MDS section to read before starting | C29: Always read before opening LM Studio
A30: Prerequisites | B30: Sessions that MUST be complete before starting this one | C30: Red if not met → do not proceed
A31: Model | B31: Which LM Studio model to use | C31: Qwen3-14B-Q4 default; Llama3.3-8B for speed-only tasks
A32: Context Tokens (est.) | B32: Estimated tokens this session will consume | C32: Stay under 8,000 total
A33: System Block | B33: The system prompt preamble to paste first | C33: Always the same base block + FR
A34: LM Studio Prompt | B34: Exact prompt to paste after the system block | C34: Do not paraphrase — paste verbatim
A35: Test You Write First | B35: The Go test to write BEFORE opening LM Studio | C35: Run it — confirm it FAILS first
... A42: Notes | B42: Free-form notes | C42: Document deviations from expected output
A44: THE THREE RULES (never break these)
A46: Rule 1 | B46: YOU write the test. The MODEL writes the implementation. | C46: Never ask model to write test AND implementation in same session
A47: Rule 2 | B47: One function per session. Reset session on 2nd consecutive failure. | C47: Fresh context = better output
A48: Rule 3 | B48: Use Claude for architecture decisions. LM Studio for code generation. | C48: Hybrid approach — Claude is free in this chat
A50: CONTEXT BUDGET PER SESSION
A51: System block | B51: ~500 tokens | C51: Always included
A52: FR spec (1 FR) | B52: ~100 tokens | C52: Paste only the relevant FR line
A53: DDS scaffold | B53: ~400 tokens | C53: Paste only the relevant function scaffold
A54: Your test | B54: ~300 tokens | C54: Paste the failing test
A55: REMAINING BUDGET | B55: ~6,700 tokens | C55: The model's actual working space
...

Sheet ✅ Definition of Done
A1: DEFINITION OF DONE — every task must pass ALL checks in its category before status → Done
A2: Check ID | B2: Category | C2: Exact Verification Step | D2: Command / Action | E2: Tool | F2: Expected Result | G2: Your Result | H2: Pass? (Y/N/NA)
A3: ▸ 0 · Every Task
A4: L0-001 | B4: 0 · Every Task | C4: Test written by YOU before LM Studio opened | D4: git log --oneline | head -5 → test file committed before impl file | E4: git | F4: Test commit timestamp < impl commit timestamp
A5: L0-002 | B5: 0 · Every Task | C5: Test FAILS before implementation (red phase confirmed) | D5: go test -run {TestName} ./... → run BEFORE pasting model output | E5: go test | F5: FAIL: undefined or compile error
A6: L0-003 | B6: 0 · Every Task | C6: go build passes with zero errors | D6: go build ./... | E6: go | F6: Exit code 0, no output
A7: L0-004 | B7: 0 · Every Task | C7: go vet passes with zero warnings | D7: go vet ./... | E7: go | F7: Exit code 0, no output
A8: L0-005 | B8: 0 · Every Task | C8: Race detector clean — run 3 times | D8: go test -race -count=3 ./internal/{module}/... | E8: go test | F8: ok (0 data races) × 3 runs
A9: L0-006 | B9: 0 · Every Task | C9: golangci-lint clean | D9: golangci-lint run --enable=errcheck,gosec,staticcheck ./... | E9: golangci-lint | F9: No issues found.
A10: L0-007 | B10: 0 · Every Task | C10: No float64 used for money anywhere in this file | D10: grep -n "float64\|math.Round\|Sprintf.*%.2f" internal/{module}/*.go | E10: grep | F10: Zero matches
A11: L0-008 | B11: 0 · Every Task | C11: No plaintext PII in any log statement | D11: grep -rni "aadhaar\|\.pan\b\|mobile_number" --include="*.go" internal/{module}/ | grep "log\." | E11: grep | F11: Zero matches
A12: L0-009 | B12: 0 · Every Task | C12: Pre-commit hook passes on staged files | D12: git add -p && git commit --dry-run | E12: git | F12: pre-commit exits 0 (no PII leak detected)
A13: L0-010 | B13: 0 · Every Task | C13: Conventional commit message format used | D13: git log -1 --format=%s | E13: git | F13: Starts with feat()|fix()|test()|db:|chore:|refactor()
A14: ▸ 1 · DB Migration
A15: L1-001 | B15: 1 · DB Migration | C15: Migration applies cleanly on empty DB | D15: goose -dir ./migrations postgres "$DSN" up | E15: goose | F15: OK migrations/NNNN_tablename.sql
A16: L1-002 | B16: 1 · DB Migration | C16: Migration rolls back cleanly (Down works) | D16: goose -dir ./migrations postgres "$DSN" down && goose ... up | E16: goose | F16: OK for both down and re-up
A17: L1-003 | B17: 1 · DB Migration | C17: All columns match DBD §6.2 exactly (type, nullable, default) | D17: psql -c "\d+ {table_name}" → compare with DBD §6.2 | E17: psql | F17: Every column type matches spec exactly
A18: L1-004 | B18: 1 · DB Migration | C18: All indexes from DBD §6.4 exist | D18: psql -c "\di+ {table_name}*" | E18: psql | F18: Each index listed in DBD §6.4 is present
A19: L1-005 | B19: 1 · DB Migration | C19: INCLUDE clause correct on LEA / CGNAT indexes | D19: psql -c "SELECT indexdef FROM pg_indexes WHERE indexname='idx_lea_ipv4_time';" | E19: psql | F19: INCLUDE (subscriber_id, stop_time) present
A20: L1-006 | B20: 1 · DB Migration | C20: Constraints enforced — insert violating row and confirm rejection | D20: psql -c "INSERT INTO invoices(cgst_amount,igst_amount,...) VALUES(71.91,143.82,...);" | E20: psql | F20: ERROR 23514 constraint violation
A21: L1-007 | B21: 1 · DB Migration | C21: Partitioned tables have ≥ 3 future partitions | D21: psql -c "SELECT tablename FROM pg_tables WHERE tablename LIKE '{table}%';" | E21: psql | F21: Parent + ≥3 monthly partition tables listed
A22: L1-008 | B22: 1 · DB Migration | C22: FK constraints enforced — insert orphan row and confirm rejection | D22: psql -c "INSERT INTO subscribers(plan_id) VALUES(9999999);" | E22: psql | F22: ERROR 23503 foreign key violation
A23: L1-009 | B23: 1 · DB Migration | C23: Row security on lea_audit_log blocks UPDATE | D23: psql -c "UPDATE lea_audit_log SET accessor_identity='x' WHERE 1=1;" | E23: psql | F23: ERROR: permission denied or 0 rows updated
A24: ▸ 2 · Unit Tests
A25: L2-001 | B25: 2 · Unit Tests | C25: Every FR for this module has ≥1 named test: TestFR_{ID}_... | D25: grep -r "func Test" internal/{module}/ | grep -c "FR_" | E25: grep | F25: Count ≥ number of FRs for this module
A26: L2-002 | B26: 2 · Unit Tests | C26: Coverage ≥ 80% (≥90% for crypto and middleware) | D26: go test -coverprofile=cov.out ./internal/{module}/... && go tool cover -func cov.out | tail -1 | E26: go test | F26: total: statements XX.X% → meets threshold
A27: L2-003 | B27: 2 · Unit Tests | C27: Happy path test passes | D27: go test -race -v -run Test{FunctionName}_HappyPath ./... | E27: go test | F27: --- PASS
A28: L2-004 | B28: 2 · Unit Tests | C28: Error / rejection path test passes | D28: go test -race -v -run Test{FunctionName}_Invalid ./... | E28: go test | F28: --- PASS (error returned as expected)
A29: L2-005 | B29: 2 · Unit Tests | C29: Edge case: zero / nil / empty input handled without panic | D29: go test -race -v -run Test{FunctionName}_Edge ./... | E29: go test | F29: --- PASS or error returned; never panic
A30: L2-006 | B30: 2 · Unit Tests | C30: Decimal precision verified to 2dp (billing module only) | D30: go test -v -run TestCalculateGst ./internal/billing/ | grep PASS | E30: go test | F30: Exact string values: 71.91 not 71.9099...
A31: ▸ 3 · Integration
A32: L3-001 | B32: 3 · Integration | C32: Docker stack healthy before running integration tests | D32: docker compose ps → all containers healthy | E32: docker | F32: All 8 containers: healthy / running
A33: L3-002 | B33: 3 · Integration | C33: Integration test suite passes with -tags=integration | D33: go test -race -tags=integration -v ./... | E33: go test | F33: All INT-* tests PASS
A34: L3-003 | B34: 3 · Integration | C34: Redis actually used on hot path (no PostgreSQL fallback hit for cached subscriber) | D34: redis-cli monitor & → run auth test → grep for "HGET subscriber:" | E34: redis-cli | F34: HGET subscriber:{username} appears in monitor output
A35: L3-004 | B35: 3 · Integration | C35: Asynq task actually enqueued in correct queue | D35: asynq task ls --queue {queue_name} --state pending → after trigger | E35: asynq CLI | F35: Task of correct type appears in queue
A36: L3-005 | B36: 3 · Integration | C36: notification_log row created for every dispatch attempt | D36: psql -c "SELECT COUNT(*) FROM notification_log WHERE subscriber_id={id};" | E36: psql | F36: Count matches number of dispatch calls made in test
A37: L3-006 | B37: 3 · Integration | C37: Idempotency: same transaction_token called twice = same TX ID, single credit | D37: go test -tags=integration -run TestWalletRecharge_Idempotent ./... | E37: go test | F37: tx1.ID == tx2.ID AND balance = single plan price
A38: L3-007 | B38: 3 · Integration | C38: DND subscriber gets suppressed_dnd in notification_log | D38: go test -tags=integration -run TestDispatcher_DND ./... | E38: go test | F38: delivery_status = suppressed_dnd in DB row
A39: L3-008 | B39: 3 · Integration | C39: Webhook HMAC: invalid signature returns 400, no state change | D39: go test -tags=integration -run TestWebhookHMAC_InvalidSignatureRejected ./... | E39: go test | F39: HTTP 400 | wallet balance unchanged
A40: ▸ 4 · Security
...

Sheet 📊 Progress Dashboard
A1: BSS/OSS DEVELOPMENT PROGRESS DASHBOARD
A2: Auto-calculated from Status columns in each task sheet — update Status cells to see progress
A4: Module / Sheet | B4: Total Tasks | C4: Done | D4: In Progress | E4: Blocked | F4: % Complete | G4: Status Bar | H4: Next Unfinished Task
A5: 🔧 Environment Setup | B5: 9 | C5: =COUNTIF('🔧 Environment Setup'!P:P,"Done") | D5: =COUNTIF('🔧 Environment Setup'!P:P,"In Progress") | E5: =COUNTIF('🔧 Environment Setup'!P:P,"Blocked") | F5: =IFERROR(C5/B5,0) | G5: =IFERROR(REPT("█",ROUND(C5/B5*20,0))&REPT("░",20-ROUND(C5/B5*20,0)),"░░░░░░░░░░░░░░░░░░░░") | H5: =IFERROR(INDEX('🔧 Environment Setup'!C:C,MATCH(FALSE,EXACT('🔧 Environment Setup'!P:P,"Done"),0)),"✅ All Done!")
A6: 🗄️ DB Migrations | B6: 15 | C6: =COUNTIF('🗄️ DB Migrations'!P:P,"Done") | D6: =COUNTIF('🗄️ DB Migrations'!P:P,"In Progress") | E6: =COUNTIF('🗄️ DB Migrations'!P:P,"Blocked") | F6: =IFERROR(C6/B6,0) | G6: =IFERROR(REPT("█",ROUND(C6/B6*20,0))&REPT("░",20-ROUND(C6/B6*20,0)),"░░░░░░░░░░░░░░░░░░░░") | H6: =IFERROR(INDEX('🗄️ DB Migrations'!C:C,MATCH(FALSE,EXACT('🗄️ DB Migrations'!P:P,"Done"),0)),"✅ All Done!")
A7: 🔐 Crypto Module | B7: 4 | C7: =COUNTIF('🔐 Crypto Module'!P:P,"Done") | D7: =COUNTIF('🔐 Crypto Module'!P:P,"In Progress") | E7: =COUNTIF('🔐 Crypto Module'!P:P,"Blocked") | F7: =IFERROR(C7/B7,0) | G7: =IFERROR(REPT("█",ROUND(C7/B7*20,0))&REPT("░",20-ROUND(C7/B7*20,0)),"░░░░░░░░░░░░░░░░░░░░") | H7: =IFERROR(INDEX('🔐 Crypto Module'!C:C,MATCH(FALSE,EXACT('🔐 Crypto Module'!P:P,"Done"),0)),"✅ All Done!")
A8: 📡 RADIUS AAA | B8: 5 | C8: =COUNTIF('📡 RADIUS AAA'!P:P,"Done") | D8: =COUNTIF('📡 RADIUS AAA'!P:P,"In Progress") | E8: =COUNTIF('📡 RADIUS AAA'!P:P,"Blocked") | F8: =IFERROR(C8/B8,0) | G8: =IFERROR(REPT("█",ROUND(C8/B8*20,0))&REPT("░",20-ROUND(C8/B8*20,0)),"░░░░░░░░░░░░░░░░░░░░") | H8: =IFERROR(INDEX('📡 RADIUS AAA'!C:C,MATCH(FALSE,EXACT('📡 RADIUS AAA'!P:P,"Done"),0)),"✅ All Done!")
A9: 💳 Billing Module | B9: 6 | C9: =COUNTIF('💳 Billing Module'!P:P,"Done") | D9: =COUNTIF('💳 Billing Module'!P:P,"In Progress") | E9: =COUNTIF('💳 Billing Module'!P:P,"Blocked") | F9: =IFERROR(C9/B9,0) | G9: =IFERROR(REPT("█",ROUND(C9/B9*20,0))&REPT("░",20-ROUND(C9/B9*20,0)),"░░░░░░░░░░░░░░░░░░░░") | H9: =IFERROR(INDEX('💳 Billing Module'!C:C,MATCH(FALSE,EXACT('💳 Billing Module'!P:P,"Done"),0)),"✅ All Done!")
A10: 🔔 Notifications | B10: 5 | C10: =COUNTIF('🔔 Notifications'!P:P,"Done") | D10: =COUNTIF('🔔 Notifications'!P:P,"In Progress") | E10: =COUNTIF('🔔 Notifications'!P:P,"Blocked") | F10: =IFERROR(C10/B10,0) | G10: =IFERROR(REPT("█",ROUND(C10/B10*20,0))&REPT("░",20-ROUND(C10/B10*20,0)),"░░░░░░░░░░░░░░░░░░░░") | H10: =IFERROR(INDEX('🔔 Notifications'!C:C,MATCH(FALSE,EXACT('🔔 Notifications'!P:P,"Done"),0)),"✅ All Done!")
A11: ⚡ FUP + Asynq | B11: 3 | C11: =COUNTIF('⚡ FUP + Asynq'!P:P,"Done") | D11: =COUNTIF('⚡ FUP + Asynq'!P:P,"In Progress") | E11: =COUNTIF('⚡ FUP + Asynq'!P:P,"Blocked") | F11: =IFERROR(C11/B11,0) | G11: =IFERROR(REPT("█",ROUND(C11/B11*20,0))&REPT("░",20-ROUND(C11/B11*20,0)),"░░░░░░░░░░░░░░░░░░░░") | H11: =IFERROR(INDEX('⚡ FUP + Asynq'!C:C,MATCH(FALSE,EXACT('⚡ FUP + Asynq'!P:P,"Done"),0)),"✅ All Done!")
A12: 🔑 API + Auth | B12: 4 | C12: =COUNTIF('🔑 API + Auth'!P:P,"Done") | D12: =COUNTIF('🔑 API + Auth'!P:P,"In Progress") | E12: =COUNTIF('🔑 API + Auth'!P:P,"Blocked") | F12: =IFERROR(C12/B12,0) | G12: =IFERROR(REPT("█",ROUND(C12/B12*20,0))&REPT("░",20-ROUND(C12/B12*20,0)),"░░░░░░░░░░░░░░░░░░░░") | H12: =IFERROR(INDEX('🔑 API + Auth'!C:C,MATCH(FALSE,EXACT('🔑 API + Auth'!P:P,"Done"),0)),"✅ All Done!")
A13: 📊 Revenue + Franchise | B13: 5 | C13: =COUNTIF('📊 Revenue + Franchise'!P:P,"Done") | D13: =COUNTIF('📊 Revenue + Franchise'!P:P,"In Progress") | E13: =COUNTIF('📊 Revenue + Franchise'!P:P,"Blocked") | F13: =IFERROR(C13/B13,0) | G13: =IFERROR(REPT("█",ROUND(C13/B13*20,0))&REPT("░",20-ROUND(C13/B13*20,0)),"░░░░░░░░░░░░░░░░░░░░") | H13: =IFERROR(INDEX('📊 Revenue + Franchise'!C:C,MATCH(FALSE,EXACT('📊 Revenue + Franchise'!P:P,"Done"),0)),"✅ All Done!")
A14: 🌐 Portal | B14: 4 | C14: =COUNTIF('🌐 Portal'!P:P,"Done") | D14: =COUNTIF('🌐 Portal'!P:P,"In Progress") | E14: =COUNTIF('🌐 Portal'!P:P,"Blocked") | F14: =IFERROR(C14/B14,0) | G14: =IFERROR(REPT("█",ROUND(C14/B14*20,0))&REPT("░",20-ROUND(C14/B14*20,0)),"░░░░░░░░░░░░░░░░░░░░") | H14: =IFERROR(INDEX('🌐 Portal'!C:C,MATCH(FALSE,EXACT('🌐 Portal'!P:P,"Done"),0)),"✅ All Done!")
A15: 🧪 Integration Tests | B15: 34 | C15: =COUNTIF('🧪 Integration Tests'!I:I,"Done") | D15: =COUNTIF('🧪 Integration Tests'!I:I,"In Progress") | E15: =COUNTIF('🧪 Integration Tests'!I:I,"Blocked") | F15: =IFERROR(C15/B15,0) | G15: =IFERROR(REPT("█",ROUND(C15/B15*20,0))&REPT("░",20-ROUND(C15/B15*20,0)),"░░░░░░░░░░░░░░░░░░░░") | H15: =IFERROR(INDEX('🧪 Integration Tests'!C:C,MATCH(FALSE,EXACT('🧪 Integration Tests'!I:I,"Done"),0)),"✅ All Done!")
A16: ⚡ NFR Load Tests | B16: 8 | C16: =COUNTIF('⚡ NFR Load Tests'!I:I,"Done") | D16: =COUNTIF('⚡ NFR Load Tests'!I:I,"In Progress") | E16: =COUNTIF('⚡ NFR Load Tests'!I:I,"Blocked") | F16: =IFERROR(C16/B16,0) | G16: =IFERROR(REPT("█",ROUND(C16/B16*20,0))&REPT("░",20-ROUND(C16/B16*20,0)),"░░░░░░░░░░░░░░░░░░░░") | H16: =IFERROR(INDEX('⚡ NFR Load Tests'!C:C,MATCH(FALSE,EXACT('⚡ NFR Load Tests'!I:I,"Done"),0)),"✅ All Done!")
A17: TOTAL | B17: =SUM(B5:B16) | C17: =SUM(C5:C16) | D17: =SUM(D5:D16) | E17: =SUM(E5:E16) | F17: =IFERROR(C17/B17,0)
A19: DoD Checks Passed (Y): | D19: ='✅ Definition of Done'!H77 | E19: of 65 total checks — all must be Y or NA before declaring 100% Done
A21: QUICK VERIFICATION COMMANDS — run these after every session to confirm Done
A22: When to run | B22: Command | C22: Expected output
A23: Every session | B23: go build ./... && go vet ./... && go test -race -count=3 ./internal/{module}/... | C23: All pass, 0 races
A24: Every session | B24: golangci-lint run --enable=errcheck,gosec,staticcheck ./... | C24: No issues found.
A25: Every session | B25: grep -rni "aadhaar|\.pan\b" --include="*.go" . | grep -v "_test\|encrypt" | grep "log\." | C25: Zero matches
A26: DB migrations | B26: goose -dir ./migrations postgres "$DSN" status | C26: All: Applied
A27: DB migrations | B27: psql -c "\d+ {table_name}" | C27: Columns match DBD §6.2
A28: Integration tests | B28: docker compose ps && go test -race -tags=integration -v ./... | C28: All INT-* PASS
A29: Billing module | B29: grep -n "float64" internal/billing/*.go | C29: Zero matches
A30: After every commit | B30: git log -1 --format="%H %s" | C30: Hash + conventional message
A31: Security check | B31: gosec ./internal/{module}/... | C31: No issues found
A32: WhatsApp | B32: psql -c "SELECT COUNT(*) FROM notification_log WHERE delivery_status='sent';" | C32: > 0 rows when test ran
A33: Before Done | B33: go test -coverprofile=cov.out ./... && go tool cover -func cov.out | tail -1 | C33: ≥80% (≥90% crypto/middleware)
A34: Load test gate | B34: radperf output: p99 ≤ 15ms | k6 output: p(99) < 200ms | C34: NFR thresholds met

Sheet 🔧 Environment Setup
A1: Session ID | B1: Phase/Week | C1: Task Title | D1: FR IDs | E1: Doc Reference | F1: Prerequisites | G1: Model | H1: Est. Context Tokens | I1: System Block (paste first) | J1: LM Studio Prompt (paste verbatim) | K1: Test You Write First (before LM Studio) | L1: Expected Output | M1: Verification Command | N1: Quality Gates | O1: Risk Flags | P1: Status | Q1: Commit Message | R1: Notes
A2: ENV-001 | B2: Week 0 | C2: Install Go 1.21 + verify | D2: — | E2: DXD §11.1 | F2: None | G2: N/A | H2: N/A | I2: You are a Go 1.21 backend engineer. Project: ISP BSS/OSS. Stack: Go 1.21, PostgreSQL 15, Redis 7.2 Sentinel, Asynq. Rules: no global state | all errors wrapped with fmt.Errorf | all DB calls use context.Context | decimal.Decimal for ALL money | never log plaintext PII (aadhaar/pan/mobile) | structured JSON logs via zerolog. Package naming: internal/{module}, pkg/{shared}. FR being implemented: [PASTE ONE FR LINE FROM SRS §2.1] DDS reference: [PASTE RELEVANT SCAFFOLD FROM DDS] | J2: N/A — manual step | K2: go version # must show go1.21.x | L2: go version go1.21.x linux/amd64 | M2: go version && go env GOPATH | N2: GOPATH set | go vet ./... on empty project = clean | O2: Wrong PATH — ensure /usr/local/go/bin in PATH | P2: Done | Q2: chore: Go 1.21 installed | R2: Verified: go1.26.5 windows/amd64 on host; tests run in golang:1.22 container
A3: ENV-002 | B3: Week 0 | C3: Install Docker + Docker Compose v2 | D3: — | E3: DXD §11.1 | F3: ENV-001 | G3: N/A | H3: N/A | I3: You are a Go 1.21 backend engineer. Project: ISP BSS/OSS. Stack: Go 1.21, PostgreSQL 15, Redis 7.2 Sentinel, Asynq. Rules: no global state | all errors wrapped with fmt.Errorf | all DB calls use context.Context | decimal.Decimal for ALL money | never log plaintext PII (aadhaar/pan/mobile) | structured JSON logs via zerolog. Package naming: internal/{module}, pkg/{shared}. FR being implemented: [PASTE ONE FR LINE FROM SRS §2.1] DDS reference: [PASTE RELEVANT SCAFFOLD FROM DDS] | J3: N/A — manual step | K3: docker compose version # must show v2.x | L3: Docker Compose version v2.x | M3: docker compose version && docker version | N3: docker ps returns empty (not error) | compose v2 not v1 | O3: docker-compose (v1) vs docker compose (v2) — must be v2 | P3: Done | Q3: chore: Docker v24+ and Compose v2 installed | R3: Verified: Docker 29.6.2 with Compose v2
A4: ENV-003 | B4: Week 0 | C4: Install LM Studio + download Qwen3-14B-Q4_K_M | D4: — | E4: Previous response §Step 1 | F4: ENV-001 | G4: N/A | H4: N/A | I4: You are a Go 1.21 backend engineer. Project: ISP BSS/OSS. Stack: Go 1.21, PostgreSQL 15, Redis 7.2 Sentinel, Asynq. Rules: no global state | all errors wrapped with fmt.Errorf | all DB calls use context.Context | decimal.Decimal for ALL money | never log plaintext PII (aadhaar/pan/mobile) | structured JSON logs via zerolog. Package naming: internal/{module}, pkg/{shared}. FR being implemented: [PASTE ONE FR LINE FROM SRS §2.1] DDS reference: [PASTE RELEVANT SCAFFOLD FROM DDS] | J4: N/A — GUI step: open LM Studio → search Qwen3-14B → download Q4_K_M variant | K4: LM Studio chat: 'Write hello world in Go' → model responds with valid Go | L4: func main() { fmt.Println("Hello, World!") } | M4: Manual: model responds in < 30 seconds on 12GB GPU | N4: VRAM usage shown in LM Studio ≤ 10GB | tokens/sec ≥ 5 | O4: Downloading wrong quantization — must be Q4_K_M not Q8 (too large for 12GB) | P4: Todo | Q4: N/A
A5: ENV-004 | B5: Week 0 | C5: Start LM Studio local server + verify OpenAI endpoint | D5: — | E5: IDD §8.1 | F5: ENV-003 | G5: N/A | H5: N/A | I5: You are a Go 1.21 backend engineer. Project: ISP BSS/OSS. Stack: Go 1.21, PostgreSQL 15, Redis 7.2 Sentinel, Asynq. Rules: no global state | all errors wrapped with fmt.Errorf | all DB calls use context.Context | decimal.Decimal for ALL money | never log plaintext PII (aadhaar/pan/mobile) | structured JSON logs via zerolog. Package naming: internal/{module}, pkg/{shared}. FR being implemented: [PASTE ONE FR LINE FROM SRS §2.1] DDS reference: [PASTE RELEVANT SCAFFOLD FROM DDS] | J5: N/A — GUI: Developer tab → toggle Start Server | K5: curl http://localhost:1234/v1/models | L5: JSON response listing Qwen3-14B model | M5: curl -s http://localhost:1234/v1/models | python3 -m json.tool | N5: HTTP 200 response | model ID present in JSON | O5: Firewall blocking port 1234 — add ufw allow 1234/tcp if needed | P5: Todo | Q5: N/A
A6: ENV-005 | B6: Week 0 | C6: Init Go module + project structure | D6: — | E6: DXD §11.2 | F6: ENV-001 | G6: N/A | H6: N/A | I6: You are a Go 1.21 backend engineer. Project: ISP BSS/OSS. Stack: Go 1.21, PostgreSQL 15, Redis 7.2 Sentinel, Asynq. Rules: no global state | all errors wrapped with fmt.Errorf | all DB calls use context.Context | decimal.Decimal for ALL money | never log plaintext PII (aadhaar/pan/mobile) | structured JSON logs via zerolog. Package naming: internal/{module}, pkg/{shared}. FR being implemented: [PASTE ONE FR LINE FROM SRS §2.1] DDS reference: [PASTE RELEVANT SCAFFOLD FROM DDS] | J6: N/A — manual: mkdir isp-bss-oss && cd isp-bss-oss go mod init github.com/yourorg/isp-bss-oss mkdir -p cmd/radiusd cmd/api internal/{radius,billing,fup,notifications,revenue,franchise,cgnat,health,middleware,tasks} pkg/crypto web/portal migrations | K6: go build ./... # should succeed on empty module | L6: Exit code 0, no errors | M6: go build ./... && go vet ./... | N6: go.mod exists | all directories created | go vet clean | O6: Module path must match import paths used in code | P6: Done | Q6: chore: init Go module and project layout
A7: ENV-006 | B7: Week 0 | C7: Add core Go dependencies | D7: — | E7: DXD §11.1 | F7: ENV-005 | G7: N/A | H7: N/A | I7: You are a Go 1.21 backend engineer. Project: ISP BSS/OSS. Stack: Go 1.21, PostgreSQL 15, Redis 7.2 Sentinel, Asynq. Rules: no global state | all errors wrapped with fmt.Errorf | all DB calls use context.Context | decimal.Decimal for ALL money | never log plaintext PII (aadhaar/pan/mobile) | structured JSON logs via zerolog. Package naming: internal/{module}, pkg/{shared}. FR being implemented: [PASTE ONE FR LINE FROM SRS §2.1] DDS reference: [PASTE RELEVANT SCAFFOLD FROM DDS] | J7: N/A — manual: go get layeh.com/radius@latest go get github.com/go-redis/redis/v9 go get github.com/jackc/pgx/v5 go get github.com/shopspring/decimal go get github.com/hibiken/asynq go get github.com/rs/zerolog go get github.com/golang-jwt/jwt/v5 go get github.com/stretchr/testify go get github.com/pressly/goose/v3/cmd/goose@latest | K7: go build ./... && go mod tidy | L7: go.sum populated, all deps resolved | M7: go build ./... && cat go.sum | wc -l # should be > 50 lines | N7: No replace directives needed | go mod tidy produces no changes | O7: layeh.com/radius may need manual version pin — check latest on pkg.go.dev | P7: Done | Q7: chore: add core dependencies to go.mod
A8: ENV-007 | B8: Week 0 | C8: Start Docker infrastructure stack | D8: — | E8: IDD §8.2 | F8: ENV-002 | G8: N/A | H8: N/A | I8: You are a Go 1.21 backend engineer. Project: ISP BSS/OSS. Stack: Go 1.21, PostgreSQL 15, Redis 7.2 Sentinel, Asynq. Rules: no global state | all errors wrapped with fmt.Errorf | all DB calls use context.Context | decimal.Decimal for ALL money | never log plaintext PII (aadhaar/pan/mobile) | structured JSON logs via zerolog. Package naming: internal/{module}, pkg/{shared}. FR being implemented: [PASTE ONE FR LINE FROM SRS §2.1] DDS reference: [PASTE RELEVANT SCAFFOLD FROM DDS] | J8: N/A — create .env from .env.example then: docker compose up -d postgres_primary redis_primary redis_replica_1 redis_replica_2 redis_sentinel_1 redis_sentinel_2 redis_sentinel_3 gotenberg_engine | K8: docker compose ps # all containers healthy | L8: All containers status = healthy or running | M8: docker compose ps && redis-cli -p 26379 sentinel master bss_master | N8: PostgreSQL responds to pg_isready | Redis Sentinel elected a master | Gotenberg returns 200 on /health | O8: Sentinel may take 10-15s to elect master — wait before testing | P8: Done | Q8: N/A
A9: ENV-008 | B9: Week 0 | C9: Install golangci-lint + pre-commit PII hook | D9: NFR-SEC-002 | E9: TST §13.5 | F9: ENV-005 | G9: N/A | H9: N/A | I9: You are a Go 1.21 backend engineer. Project: ISP BSS/OSS. Stack: Go 1.21, PostgreSQL 15, Redis 7.2 Sentinel, Asynq. Rules: no global state | all errors wrapped with fmt.Errorf | all DB calls use context.Context | decimal.Decimal for ALL money | never log plaintext PII (aadhaar/pan/mobile) | structured JSON logs via zerolog. Package naming: internal/{module}, pkg/{shared}. FR being implemented: [PASTE ONE FR LINE FROM SRS §2.1] DDS reference: [PASTE RELEVANT SCAFFOLD FROM DDS] | J9: N/A — manual: curl -sSfL https://raw.githubusercontent.com/golangci/golangci-lint/master/install.sh | sh -s -- -b $(go env GOPATH)/bin v1.55.2 cat > .git/hooks/pre-commit << 'EOF' #!/bin/sh grep -rni "aadhaar\|\.pan\b" --include="*.go" . | grep -v "_test.go\|encrypt\|db\." | grep "log\.\|Print" && echo "PII LEAK DETECTED" && exit 1 exit 0 EOF chmod +x .git/hooks/pre-commit | K9: golangci-lint version && echo 'test' > /tmp/t.go && .git/hooks/pre-commit | L9: golangci-lint version shown | hook exits 0 on clean code | M9: golangci-lint run ./... --timeout 2m # expect 'no issues found' on empty project | N9: Hook blocks commit when test file contains 'log.Info(aadhaar)' | O9: Hook path must be .git/hooks/pre-commit not pre-commit.sh | P9: Done | Q9: chore: add golangci-lint and PII pre-commit hook
A10: ENV-009 | B10: Week 0 | C10: Create compliance.sh — automated DoD verification script | D10: L0-003..L0-008 (DoD checks) | E10: TST §13.5, DoD Level 0 | F10: ENV-006 (Go installed), ENV-008 (golangci-lint installed) | G10: Llama3.1-8B-Q5_K_M | H10: ~3,000 | I10: You are a Go 1.21 backend engineer. Project: ISP BSS/OSS. Stack: Go 1.21, PostgreSQL 15, Redis 7.2 Sentinel, Asynq. Rules: no global state | all errors wrapped with fmt.Errorf | all DB calls use context.Context | decimal.Decimal for ALL money | never log plaintext PII (aadhaar/pan/mobile) | structured JSON logs via zerolog. Package naming: internal/{module}, pkg/{shared}. FR being implemented: [PASTE ONE FR LINE FROM SRS §2.1] DDS reference: [PASTE RELEVANT SCAFFOLD FROM DDS] | J10: System block (no FR needed — this is a tooling task, not application code). Generate scripts/compliance.sh — a Bash script that accepts one argument: the Go package path. Example usage: ./scripts/compliance.sh internal/billing The script must run these checks IN ORDER and exit 1 on first failure: 1. go build ./... Label: "BUILD" 2. go vet ./... Label: "VET" 3. go test -race -count=3 ./{package}/... Label: "RACE (×3)" 4. golangci-lint run --enable=errcheck,gosec,staticcheck ./{package}/... Label: "LINT" 5. grep -rn "float64\|math.Round\|fmt.Sprintf.*%.2f" {package}/*.go Label: "FLOAT64 CHECK" Pass = zero matches 6. grep -rni "aadhaar\|\.pan\b\|mobile_number" --include="*.go" {package}/ | grep -v "_test.go\|encrypt\|db\." | grep "log\." Label: "PII LOG CHECK" Pass = zero matches 7. go test -coverprofile=/tmp/cov.out ./{package}/... && go tool cover -func /tmp/cov.out | tail -1 Label: "COVERAGE" Print result — do not fail on coverage threshold (user checks manually) Print a coloured PASS (green) or FAIL (red) next to each label. Print a final summary line: "N/7 checks passed for {package}" Script must be executable (chmod +x) and use #!/usr/bin/env bash at the top. | K10: # Run against crypto module (should all pass after CRY-004): chmod +x scripts/compliance.sh ./scripts/compliance.sh pkg/crypto # Expected output format: # [PASS] BUILD # [PASS] VET # [PASS] RACE (×3) # [PASS] LINT # [PASS] FLOAT64 CHECK # [PASS] PII LOG CHECK # [PASS] COVERAGE: 91.3% # 7/7 checks passed for pkg/crypto | L10: scripts/compliance.sh file created. When run: coloured PASS/FAIL per check. Final line: "7/7 checks passed for {package}" | M10: chmod +x scripts/compliance.sh ./scripts/compliance.sh pkg/crypto # run on crypto module first ./scripts/compliance.sh internal/billing echo "Exit code: $?" # must be 0 for all passing | N10: Script exits 1 on first failure (not silently continues) | Float64 grep returns non-zero when float64 found | PII grep returns non-zero when log.Info(aadhaar) found | Coverage line printed but does not cause failure | Coloured output: green=PASS red=FAIL | O10: Model may use 'exit 0' at end regardless — must use 'exit 1' on failure | grep exit code is 1 when no match (pass) and 0 when match (fail) — logic is INVERTED for grep checks | Must handle packages with no .go files gracefully | P10: Done | Q10: chore(scripts): ENV-009 add compliance.sh automated DoD check runner | R10: Addresses DoD fatigue gap — 65 manual checks reduced to 1 command per session

Sheet 🗄️ DB Migrations
A1: Session ID | B1: Phase/Week | C1: Task Title | D1: FR IDs | E1: Doc Reference | F1: Prerequisites | G1: Model | H1: Est. Context Tokens | I1: System Block (paste first) | J1: LM Studio Prompt (paste verbatim) | K1: Test You Write First (before LM Studio) | L1: Expected Output | M1: Verification Command | N1: Quality Gates | O1: Risk Flags | P1: Status | Q1: Commit Message | R1: Notes
A2: DB-001 | B2: Week 1 | C2: Migration: franchises table | D2: FR-FRN-001 | E2: DBD §6.2 franchises | F2: ENV-007 | G2: Llama3.1-8B-Q5_K_M | H2: ~2,500 | I2: You are a Go 1.21 backend engineer. Project: ISP BSS/OSS. Stack: Go 1.21, PostgreSQL 15, Redis 7.2 Sentinel, Asynq. Rules: no global state | all errors wrapped with fmt.Errorf | all DB calls use context.Context | decimal.Decimal for ALL money | never log plaintext PII (aadhaar/pan/mobile) | structured JSON logs via zerolog. Package naming: internal/{module}, pkg/{shared}. FR being implemented: [PASTE ONE FR LINE FROM SRS §2.1] DDS reference: [PASTE RELEVANT SCAFFOLD FROM DDS] | J2: Generate a goose migration SQL file for the table below. PostgreSQL 15 syntax. Include +goose Up and +goose Down sections. In +goose Down, DROP TABLE CASCADE. Add ONLY the indexes listed — no extras. Use TIMESTAMPTZ not TIMESTAMP. Never use SERIAL for tables that will be partitioned — use BIGSERIAL. Table spec: [PASTE TABLE FROM DBD §6.2] Indexes: [PASTE INDEXES FOR THIS TABLE FROM DBD §6.4] | K2: psql -h localhost -U postgres -d isp_bss_oss -c '\d+ franchises' | L2: Table franchises exists with all columns | commission_rate_pct NUMERIC(5,2) NOT NULL | M2: goose -dir ./migrations postgres "$DSN" status | N2: goose status shows DB-001 = applied | \d+ shows correct types and NOT NULL constraints | O2: Model may use TEXT for commission_rate — must be NUMERIC(5,2) | P2: Done | Q2: db: add franchises table migration | R2: Switched to Llama3.1-8B (5GB VRAM) — frees 7GB for Docker stack. 8B is sufficient for boilerplate SQL generation.
A3: DB-002 | B3: Week 1 | C3: Migration: plans table | D3: FR-AAA-004, FR-FUP-001 | E3: DBD §6.2 plans | F3: DB-001 | G3: Llama3.1-8B-Q5_K_M | H3: ~2,500 | I3: You are a Go 1.21 backend engineer. Project: ISP BSS/OSS. Stack: Go 1.21, PostgreSQL 15, Redis 7.2 Sentinel, Asynq. Rules: no global state | all errors wrapped with fmt.Errorf | all DB calls use context.Context | decimal.Decimal for ALL money | never log plaintext PII (aadhaar/pan/mobile) | structured JSON logs via zerolog. Package naming: internal/{module}, pkg/{shared}. FR being implemented: [PASTE ONE FR LINE FROM SRS §2.1] DDS reference: [PASTE RELEVANT SCAFFOLD FROM DDS] | J3: Generate a goose migration SQL file for the table below. PostgreSQL 15 syntax. Include +goose Up and +goose Down sections. In +goose Down, DROP TABLE CASCADE. Add ONLY the indexes listed — no extras. Use TIMESTAMPTZ not TIMESTAMP. Never use SERIAL for tables that will be partitioned — use BIGSERIAL. Table spec: [PASTE TABLE FROM DBD §6.2] Indexes: [PASTE INDEXES FOR THIS TABLE FROM DBD §6.4] | K3: psql ... -c '\d+ plans' | L3: fup_threshold_bytes BIGINT | franchise_id FK nullable | price NUMERIC(12,2) | M3: goose ... status && psql -c "INSERT INTO plans(name,rate_limit_string,volume_gb,fup_threshold_bytes,price,validity_days) VALUES('test','10M/10M',10,10737418240,199.00,30);" | N3: FK to franchises exists | INSERT succeeds without franchise_id | O3: Model may forget FK to franchises — check carefully | P3: Done | Q3: db: add plans table migration | R3: Switched to Llama3.1-8B (5GB VRAM) — frees 7GB for Docker stack. 8B is sufficient for boilerplate SQL generation.
A4: DB-003 | B4: Week 1 | C4: Migration: subscribers table | D4: FR-AAA-001..004 | E4: DBD §6.2 subscribers | F4: DB-002 | G4: Llama3.1-8B-Q5_K_M | H4: ~3,000 | I4: You are a Go 1.21 backend engineer. Project: ISP BSS/OSS. Stack: Go 1.21, PostgreSQL 15, Redis 7.2 Sentinel, Asynq. Rules: no global state | all errors wrapped with fmt.Errorf | all DB calls use context.Context | decimal.Decimal for ALL money | never log plaintext PII (aadhaar/pan/mobile) | structured JSON logs via zerolog. Package naming: internal/{module}, pkg/{shared}. FR being implemented: [PASTE ONE FR LINE FROM SRS §2.1] DDS reference: [PASTE RELEVANT SCAFFOLD FROM DDS] | J4: Generate a goose migration SQL file for the table below. PostgreSQL 15 syntax. Include +goose Up and +goose Down sections. In +goose Down, DROP TABLE CASCADE. Add ONLY the indexes listed — no extras. Use TIMESTAMPTZ not TIMESTAMP. Never use SERIAL for tables that will be partitioned — use BIGSERIAL. Table spec: [PASTE TABLE FROM DBD §6.2] Indexes: [PASTE INDEXES FOR THIS TABLE FROM DBD §6.4] | K4: psql ... -c '\d+ subscribers' | L4: status VARCHAR(20) | dunning_state VARCHAR(20) DEFAULT 'active' | dnd_opt_out BOOLEAN DEFAULT FALSE | M4: psql -c "SELECT column_name,data_type,column_default FROM information_schema.columns WHERE table_name='subscribers' ORDER BY ordinal_position;" | N4: idx_sub_auth index created | idx_sub_expiry partial index created | username UNIQUE constraint | O4: Model may omit dunning_state column (new in v2) — verify it is present | P4: Done | Q4: db: add subscribers table migration | R4: Switched to Llama3.1-8B (5GB VRAM) — frees 7GB for Docker stack. 8B is sufficient for boilerplate SQL generation.
A5: DB-004 | B5: Week 1 | C5: Migration: encryption_keys table | D5: FR-SEC-002, FR-SEC-003 | E5: DBD §6.2 encryption_keys | F5: DB-003 | G5: Llama3.1-8B-Q5_K_M | H5: ~2,000 | I5: You are a Go 1.21 backend engineer. Project: ISP BSS/OSS. Stack: Go 1.21, PostgreSQL 15, Redis 7.2 Sentinel, Asynq. Rules: no global state | all errors wrapped with fmt.Errorf | all DB calls use context.Context | decimal.Decimal for ALL money | never log plaintext PII (aadhaar/pan/mobile) | structured JSON logs via zerolog. Package naming: internal/{module}, pkg/{shared}. FR being implemented: [PASTE ONE FR LINE FROM SRS §2.1] DDS reference: [PASTE RELEVANT SCAFFOLD FROM DDS] | J5: Generate a goose migration SQL file for the table below. PostgreSQL 15 syntax. Include +goose Up and +goose Down sections. In +goose Down, DROP TABLE CASCADE. Add ONLY the indexes listed — no extras. Use TIMESTAMPTZ not TIMESTAMP. Never use SERIAL for tables that will be partitioned — use BIGSERIAL. Table spec: [PASTE TABLE FROM DBD §6.2] Indexes: [PASTE INDEXES FOR THIS TABLE FROM DBD §6.4] | K5: psql ... -c '\d+ encryption_keys' | L5: version_id VARCHAR(10) UNIQUE | key_hash VARCHAR(64) | status VARCHAR(10) DEFAULT 'active' | M5: psql -c "INSERT INTO encryption_keys(version_id,key_hash) VALUES('v1','abc123');" | N5: version_id UNIQUE constraint enforced | INSERT succeeds | O5: Model may add key_material column — must NOT exist (stored in secret manager only) | P5: Done | Q5: db: add encryption_keys table migration | R5: Switched to Llama3.1-8B (5GB VRAM) — frees 7GB for Docker stack. 8B is sufficient for boilerplate SQL generation.
A6: DB-005 | B6: Week 1 | C6: Migration: kyc_verifications table | D6: FR-SEC-002, FR-SEC-003 | E6: DBD §6.2 kyc_verifications | F6: DB-004 | G6: Llama3.1-8B-Q5_K_M | H6: ~2,500 | I6: You are a Go 1.21 backend engineer. Project: ISP BSS/OSS. Stack: Go 1.21, PostgreSQL 15, Redis 7.2 Sentinel, Asynq. Rules: no global state | all errors wrapped with fmt.Errorf | all DB calls use context.Context | decimal.Decimal for ALL money | never log plaintext PII (aadhaar/pan/mobile) | structured JSON logs via zerolog. Package naming: internal/{module}, pkg/{shared}. FR being implemented: [PASTE ONE FR LINE FROM SRS §2.1] DDS reference: [PASTE RELEVANT SCAFFOLD FROM DDS] | J6: Generate a goose migration SQL file for the table below. PostgreSQL 15 syntax. Include +goose Up and +goose Down sections. In +goose Down, DROP TABLE CASCADE. Add ONLY the indexes listed — no extras. Use TIMESTAMPTZ not TIMESTAMP. Never use SERIAL for tables that will be partitioned — use BIGSERIAL. Table spec: [PASTE TABLE FROM DBD §6.2] Indexes: [PASTE INDEXES FOR THIS TABLE FROM DBD §6.4] | K6: psql ... -c '\d+ kyc_verifications' | L6: aadhaar_encrypted TEXT nullable | key_version_id FK → encryption_keys.version_id | M6: psql -c "INSERT INTO kyc_verifications(subscriber_id,key_version_id) VALUES(1,'v1');" | N6: FK to encryption_keys enforced | FK to subscribers enforced | O6: Model may store plaintext aadhaar — column must be TEXT named aadhaar_encrypted | P6: Done | Q6: db: add kyc_verifications table migration | R6: Switched to Llama3.1-8B (5GB VRAM) — frees 7GB for Docker stack. 8B is sufficient for boilerplate SQL generation.
A7: DB-006 | B7: Week 1 | C7: Migration: gst_rates + invoices tables | D7: FR-BIL-001, FR-BIL-007 | E7: DBD §6.2 invoices | F7: DB-003 | G7: Llama3.1-8B-Q5_K_M | H7: ~3,000 | I7: You are a Go 1.21 backend engineer. Project: ISP BSS/OSS. Stack: Go 1.21, PostgreSQL 15, Redis 7.2 Sentinel, Asynq. Rules: no global state | all errors wrapped with fmt.Errorf | all DB calls use context.Context | decimal.Decimal for ALL money | never log plaintext PII (aadhaar/pan/mobile) | structured JSON logs via zerolog. Package naming: internal/{module}, pkg/{shared}. FR being implemented: [PASTE ONE FR LINE FROM SRS §2.1] DDS reference: [PASTE RELEVANT SCAFFOLD FROM DDS] | J7: Generate a goose migration SQL file for the table below. PostgreSQL 15 syntax. Include +goose Up and +goose Down sections. In +goose Down, DROP TABLE CASCADE. Add ONLY the indexes listed — no extras. Use TIMESTAMPTZ not TIMESTAMP. Never use SERIAL for tables that will be partitioned — use BIGSERIAL. Table spec: [PASTE TABLE FROM DBD §6.2] Indexes: [PASTE INDEXES FOR THIS TABLE FROM DBD §6.4] IMPORTANT: also create gst_rates table (id,cgst_rate,sgst_rate,igst_rate,effective_from) and add chk_gst_logic constraint on invoices: (cgst_amount>0 AND igst_amount=0) OR (igst_amount>0 AND cgst_amount=0) OR (cgst_amount=0 AND igst_amount=0) | K7: psql -c "INSERT INTO invoices(subscriber_id,base_amount,cgst_amount,sgst_amount,igst_amount,total_amount,gst_rate_id,gb_included,gb_used) VALUES(1,799.00,71.91,71.91,0,942.82,1,3300,2847);" | L7: INSERT succeeds for valid intrastate invoice | M7: psql -c "INSERT INTO invoices(subscriber_id,base_amount,cgst_amount,sgst_amount,igst_amount,total_amount,gst_rate_id,gb_included,gb_used) VALUES(1,799.00,71.91,0,143.82,1014.73,1,3300,2847);" # MUST fail with constraint violation | N7: chk_gst_logic constraint blocks cgst + igst both non-zero | gb_included and gb_used columns present | O7: Model forgets chk_gst_logic constraint | forgets gb_included/gb_used columns | P7: Done | Q7: db: add gst_rates and invoices table migration | R7: Switched to Llama3.1-8B (5GB VRAM) — frees 7GB for Docker stack. 8B is sufficient for boilerplate SQL generation.
A8: DB-007 | B8: Week 1 | C8: Migration: wallet_ledgers table | D8: FR-BIL-003, FR-BIL-005, FR-REV-002 | E8: DBD §6.2 wallet_ledgers | F8: DB-003 | G8: Llama3.1-8B-Q5_K_M | H8: ~2,500 | I8: You are a Go 1.21 backend engineer. Project: ISP BSS/OSS. Stack: Go 1.21, PostgreSQL 15, Redis 7.2 Sentinel, Asynq. Rules: no global state | all errors wrapped with fmt.Errorf | all DB calls use context.Context | decimal.Decimal for ALL money | never log plaintext PII (aadhaar/pan/mobile) | structured JSON logs via zerolog. Package naming: internal/{module}, pkg/{shared}. FR being implemented: [PASTE ONE FR LINE FROM SRS §2.1] DDS reference: [PASTE RELEVANT SCAFFOLD FROM DDS] | J8: Generate a goose migration SQL file for the table below. PostgreSQL 15 syntax. Include +goose Up and +goose Down sections. In +goose Down, DROP TABLE CASCADE. Add ONLY the indexes listed — no extras. Use TIMESTAMPTZ not TIMESTAMP. Never use SERIAL for tables that will be partitioned — use BIGSERIAL. Table spec: [PASTE TABLE FROM DBD §6.2] Indexes: [PASTE INDEXES FOR THIS TABLE FROM DBD §6.4] | K8: psql -c "INSERT INTO wallet_ledgers(subscriber_id,entry_type,amount,balance_after,transaction_token) VALUES(1,'credit',799.00,799.00,'tok_test_001');" | L8: INSERT succeeds | M8: psql -c "INSERT INTO wallet_ledgers(subscriber_id,entry_type,amount,balance_after,transaction_token) VALUES(1,'credit',799.00,799.00,'tok_test_001');" # second insert MUST fail (unique token) | N8: UNIQUE constraint on transaction_token | partial index (WHERE token IS NOT NULL) created | O8: Model may make transaction_token NOT NULL — must be NULLABLE (cash payments have no token) | P8: Done | Q8: db: add wallet_ledgers table migration | R8: Switched to Llama3.1-8B (5GB VRAM) — frees 7GB for Docker stack. 8B is sufficient for boilerplate SQL generation.
A9: DB-008 | B9: Week 2 | C9: Migration: notification_templates + notification_log | D9: FR-NOTIF-009, FR-NOTIF-010, FR-NOTIF-011 | E9: DBD §6.2 notification_log | F9: DB-003 | G9: Llama3.1-8B-Q5_K_M | H9: ~3,000 | I9: You are a Go 1.21 backend engineer. Project: ISP BSS/OSS. Stack: Go 1.21, PostgreSQL 15, Redis 7.2 Sentinel, Asynq. Rules: no global state | all errors wrapped with fmt.Errorf | all DB calls use context.Context | decimal.Decimal for ALL money | never log plaintext PII (aadhaar/pan/mobile) | structured JSON logs via zerolog. Package naming: internal/{module}, pkg/{shared}. FR being implemented: [PASTE ONE FR LINE FROM SRS §2.1] DDS reference: [PASTE RELEVANT SCAFFOLD FROM DDS] | J9: Generate a goose migration SQL file for the table below. PostgreSQL 15 syntax. Include +goose Up and +goose Down sections. In +goose Down, DROP TABLE CASCADE. Add ONLY the indexes listed — no extras. Use TIMESTAMPTZ not TIMESTAMP. Never use SERIAL for tables that will be partitioned — use BIGSERIAL. Table spec: [PASTE TABLE FROM DBD §6.2] Indexes: [PASTE INDEXES FOR THIS TABLE FROM DBD §6.4] Create both notification_templates and notification_log tables. notification_log.provider_message_id needs an index for delivery callback lookups. notification_log uses BIGSERIAL pk. | K9: psql -c '\d+ notification_log' | L9: BIGSERIAL pk | delivery_status DEFAULT 'sent' | provider_message_id nullable | idx_notif_provider_id index | M9: psql -c "INSERT INTO notification_templates(id,channel,template_name,event_trigger) VALUES('TMPL-001','whatsapp','fup_warning','fup_warning');" | N9: idx_notif_subscriber index created | idx_notif_provider_id partial index created | FK to subscribers and notification_templates | O9: Model may make template_id NOT NULL on notification_log — must be NULLABLE (system events may not have template) | P9: Done | Q9: db: add notification_templates and notification_log migrations | R9: Switched to Llama3.1-8B (5GB VRAM) — frees 7GB for Docker stack. 8B is sufficient for boilerplate SQL generation.
A10: DB-009 | B10: Week 2 | C10: Migration: tickets table | D10: FR-SUB-004 | E10: DBD §6.2 tickets | F10: DB-003 | G10: Llama3.1-8B-Q5_K_M | H10: ~2,000 | I10: You are a Go 1.21 backend engineer. Project: ISP BSS/OSS. Stack: Go 1.21, PostgreSQL 15, Redis 7.2 Sentinel, Asynq. Rules: no global state | all errors wrapped with fmt.Errorf | all DB calls use context.Context | decimal.Decimal for ALL money | never log plaintext PII (aadhaar/pan/mobile) | structured JSON logs via zerolog. Package naming: internal/{module}, pkg/{shared}. FR being implemented: [PASTE ONE FR LINE FROM SRS §2.1] DDS reference: [PASTE RELEVANT SCAFFOLD FROM DDS] | J10: Generate a goose migration SQL file for the table below. PostgreSQL 15 syntax. Include +goose Up and +goose Down sections. In +goose Down, DROP TABLE CASCADE. Add ONLY the indexes listed — no extras. Use TIMESTAMPTZ not TIMESTAMP. Never use SERIAL for tables that will be partitioned — use BIGSERIAL. Table spec: [PASTE TABLE FROM DBD §6.2] Indexes: [PASTE INDEXES FOR THIS TABLE FROM DBD §6.4] | K10: psql -c '\d+ tickets' | L10: status DEFAULT 'open' | category constraint in (connectivity,billing,plan_change,other) | M10: psql -c "INSERT INTO tickets(subscriber_id,category,description) VALUES(1,'billing','test ticket');" | N10: Status CHECK constraint | category CHECK constraint | updated_at has trigger | O10: Model may forget updated_at trigger | P10: Done | Q10: db: add tickets table migration | R10: Switched to Llama3.1-8B (5GB VRAM) — frees 7GB for Docker stack. 8B is sufficient for boilerplate SQL generation.
A11: DB-010 | B11: Week 2 | C11: Migration: subscriber_session_history (partitioned) | D11: FR-NET-001, FR-NET-003 | E11: DBD §6.2 subscriber_session_history | F11: DB-003 | G11: Qwen3-14B-Q4_K_M | H11: ~3,000 | I11: You are a Go 1.21 backend engineer. Project: ISP BSS/OSS. Stack: Go 1.21, PostgreSQL 15, Redis 7.2 Sentinel, Asynq. Rules: no global state | all errors wrapped with fmt.Errorf | all DB calls use context.Context | decimal.Decimal for ALL money | never log plaintext PII (aadhaar/pan/mobile) | structured JSON logs via zerolog. Package naming: internal/{module}, pkg/{shared}. FR being implemented: [PASTE ONE FR LINE FROM SRS §2.1] DDS reference: [PASTE RELEVANT SCAFFOLD FROM DDS] | J11: Generate a goose migration SQL file for the table below. PostgreSQL 15 syntax. Include +goose Up and +goose Down sections. In +goose Down, DROP TABLE CASCADE. Add ONLY the indexes listed — no extras. Use TIMESTAMPTZ not TIMESTAMP. Never use SERIAL for tables that will be partitioned — use BIGSERIAL. Table spec: [PASTE TABLE FROM DBD §6.2] Indexes: [PASTE INDEXES FOR THIS TABLE FROM DBD §6.4] IMPORTANT: This table uses RANGE partitioning on start_time (monthly). Use pg_partman: SELECT partman.create_parent('public.subscriber_session_history','start_time','monthly',3). Include this in +goose Up. Also create idx_lea_ipv4_time and idx_nas_active_cleanup indexes. | K11: psql -c "SELECT tablename FROM pg_tables WHERE tablename LIKE 'subscriber_session_history%';" | L11: Parent table + at least 3 monthly partition tables | M11: psql -c "SELECT partman.check_parent('public.subscriber_session_history');" | N11: Partitions created | idx_lea_ipv4_time INCLUDE clause correct | Partial index WHERE stop_time IS NULL | O11: Model may skip INCLUDE clause on LEA index — must include subscriber_id and stop_time | P11: Done | Q11: db: add subscriber_session_history partitioned table migration | R11: Was marked Done but could not apply: required pg_partman, absent from the postgres:15-alpine image IDD 8.2 pins. Rewritten to use native PostgreSQL 15 declarative partitioning with create_monthly_partitions(). Verified by scripts/verify_migrations.sh (goose up, down-to 0, up again).
A12: DB-011 | B12: Week 2 | C12: Migration: cgnat_allocations (partitioned) | D12: FR-NET-001, FR-NET-002 | E12: DBD §6.2 cgnat_allocations | F12: DB-003 | G12: Qwen3-14B-Q4_K_M | H12: ~2,500 | I12: You are a Go 1.21 backend engineer. Project: ISP BSS/OSS. Stack: Go 1.21, PostgreSQL 15, Redis 7.2 Sentinel, Asynq. Rules: no global state | all errors wrapped with fmt.Errorf | all DB calls use context.Context | decimal.Decimal for ALL money | never log plaintext PII (aadhaar/pan/mobile) | structured JSON logs via zerolog. Package naming: internal/{module}, pkg/{shared}. FR being implemented: [PASTE ONE FR LINE FROM SRS §2.1] DDS reference: [PASTE RELEVANT SCAFFOLD FROM DDS] | J12: Generate a goose migration SQL file for the table below. PostgreSQL 15 syntax. Include +goose Up and +goose Down sections. In +goose Down, DROP TABLE CASCADE. Add ONLY the indexes listed — no extras. Use TIMESTAMPTZ not TIMESTAMP. Never use SERIAL for tables that will be partitioned — use BIGSERIAL. Table spec: [PASTE TABLE FROM DBD §6.2] Indexes: [PASTE INDEXES FOR THIS TABLE FROM DBD §6.4] Partitioned on allocated_at (monthly) via pg_partman. Create idx_cgnat_lea index with INCLUDE(subscriber_id,port_start,port_end,released_at). | K12: psql -c "SELECT tablename FROM pg_tables WHERE tablename LIKE 'cgnat_allocations%';" | L12: Parent + 3 monthly partitions | M12: psql -c "\d+ cgnat_allocations" | N12: Port range columns INTEGER | idx_cgnat_lea INCLUDE clause correct | O12: Model may use TIMESTAMP instead of TIMESTAMPTZ for allocated_at | P12: Done | Q12: db: add cgnat_allocations partitioned table migration | R12: Same pg_partman problem as DB-010; now uses create_monthly_partitions() from migration 010. 4 monthly partitions confirmed (current + 3 ahead), and a current-month insert routes correctly.
... A16: DB-015 | B16: Week 2 | C16: Run full goose migration + seed test data | D16: All DB FRs | E16: DXD §11.5 | F16: DB-001..DB-014 | G16: N/A | H16: N/A | I16: You are a Go 1.21 backend engineer. Project: ISP BSS/OSS. Stack: Go 1.21, PostgreSQL 15, Redis 7.2 Sentinel, Asynq. Rules: no global state | all errors wrapped with fmt.Errorf | all DB calls use context.Context | decimal.Decimal for ALL money | never log plaintext PII (aadhaar/pan/mobile) | structured JSON logs via zerolog. Package naming: internal/{module}, pkg/{shared}. FR being implemented: [PASTE ONE FR LINE FROM SRS §2.1] DDS reference: [PASTE RELEVANT SCAFFOLD FROM DDS] | J16: N/A — manual: goose -dir ./migrations postgres "$DSN" up psql -h localhost -U postgres -d isp_bss_oss -f scripts/seed_local.sql | K16: psql -c 'SELECT COUNT(*) FROM plans;' # expect ≥ 3 rows | L16: Migrations: all applied | Plans: 3 rows | GST rates: 1 row | M16: goose -dir ./migrations postgres "$DSN" status # all = Applied | N16: Zero failed migrations | seed data present | all FKs satisfied by seed data | O16: FK violations in seed data if insertion order is wrong — franchises before subscribers | P16: Done | Q16: db: all migrations applied and seed data loaded | R16: Full goose up / down-to 0 / up cycle now passes; previously blocked by the pg_partman migrations and by migration 003's trigger function lacking +goose StatementBegin/End, which goose split at the first internal semicolon. Run scripts/verify_migrations.sh.
A17: DB-016 | B17: Week 2 | C17: Migration: persistence-layer columns (fup_active, ledger account, KYC uniqueness) | D17: FR-FUP-001, FR-REV-002, FR-SEC-002 | E17: DBD 6.2 corrections | F17: DB-003, DB-005, DB-007 | G17: N/A | H17: N/A | J17: N/A - written while implementing internal/db against the interfaces the domain packages already declared. | K17: go test -tags=integration ./internal/db/... (TestFUPStore_SetFUPActive, TestRevenueStore_LedgerVariance, TestAPIStore_UpsertKYC) | L17: subscribers.fup_active added; wallet_ledgers.account added with CHECK; kyc_verifications gains uq_kyc_subscriber | M17: ./scripts/verify_migrations.sh && ./scripts/run_db_tests.sh | N17: goose up/down clean | FUP throttle state persists | ledger variance detects drift | KYC upsert does not duplicate | O17: Without account on wallet_ledgers the FR-REV-002 variance is zero by construction, since both recharge legs share a subscriber_id | P17: Done | Q17: db: add fup_active, wallet ledger account and KYC uniqueness | R17: Three columns the application code required that no earlier migration created. Each was found by implementing the persistence layer, not by review.

Sheet 🔐 Crypto Module
A1: Session ID | B1: Phase/Week | C1: Task Title | D1: FR IDs | E1: Doc Reference | F1: Prerequisites | G1: Model | H1: Est. Context Tokens | I1: System Block (paste first) | J1: LM Studio Prompt (paste verbatim) | K1: Test You Write First (before LM Studio) | L1: Expected Output | M1: Verification Command | N1: Quality Gates | O1: Risk Flags | P1: Status | Q1: Commit Message | R1: Notes
A2: CRY-001 | B2: Week 3 | C2: Define KeyStore interface + AESEncryptor struct | D2: FR-SEC-002, FR-SEC-003 | E2: DDS §5.5 | F2: ENV-006 | G2: Qwen3-14B-Q4_K_M | H2: ~3,500 | I2: You are a Go 1.21 backend engineer. Project: ISP BSS/OSS. Stack: Go 1.21, PostgreSQL 15, Redis 7.2 Sentinel, Asynq. Rules: no global state | all errors wrapped with fmt.Errorf | all DB calls use context.Context | decimal.Decimal for ALL money | never log plaintext PII (aadhaar/pan/mobile) | structured JSON logs via zerolog. Package naming: internal/{module}, pkg/{shared}. FR being implemented: [PASTE ONE FR LINE FROM SRS §2.1] DDS reference: [PASTE RELEVANT SCAFFOLD FROM DDS] | J2: System block + FR-SEC-002 + FR-SEC-003 + DDS §5.5 scaffold. Generate pkg/crypto/types.go containing: 1. KeyStore interface with GetKey(versionID string) ([]byte, error) 2. AESEncryptor struct with key []byte and keyVersion string fields 3. NewAESEncryptor(key []byte, version string) *AESEncryptor constructor Return ONLY the package declaration, imports, interface, struct, and constructor. No Encrypt or Decrypt methods yet. | K2: func TestNewAESEncryptor(t *testing.T) { enc := NewAESEncryptor(make([]byte, 32), "v1") assert.NotNil(t, enc) assert.Equal(t, "v1", enc.keyVersion) } | L2: Compiling pkg/crypto/types.go with correct struct fields | M2: go build ./pkg/crypto/ && go test -race ./pkg/crypto/ | N2: go vet clean | no exported fields on AESEncryptor (key must be private) | O2: Model may export key field — must be private (lowercase) | P2: Done | Q2: feat(crypto): CRY-001 AESEncryptor struct and KeyStore interface
A3: CRY-002 | B3: Week 3 | C3: Implement Encrypt method | D3: FR-SEC-002, FR-SEC-003 | E3: DDS §5.5 | F3: CRY-001 | G3: Qwen3-14B-Q4_K_M | H3: ~4,000 | I3: You are a Go 1.21 backend engineer. Project: ISP BSS/OSS. Stack: Go 1.21, PostgreSQL 15, Redis 7.2 Sentinel, Asynq. Rules: no global state | all errors wrapped with fmt.Errorf | all DB calls use context.Context | decimal.Decimal for ALL money | never log plaintext PII (aadhaar/pan/mobile) | structured JSON logs via zerolog. Package naming: internal/{module}, pkg/{shared}. FR being implemented: [PASTE ONE FR LINE FROM SRS §2.1] DDS reference: [PASTE RELEVANT SCAFFOLD FROM DDS] | J3: System block + DDS §5.5 Encrypt code pattern. Add method (e *AESEncryptor) Encrypt(plaintext string) (string, error) to pkg/crypto/encryptor.go. Format: "{keyVersion}:{base64(nonce+ciphertext)}" Use AES-GCM. Use io.ReadFull(rand.Reader,nonce). Return versioned ciphertext string. | K3: func TestEncrypt_ProducesVersionedCiphertext(t *testing.T) { key := make([]byte, 32) enc := NewAESEncryptor(key, "v1") ct, err := enc.Encrypt("123456789012") assert.NoError(t, err) assert.True(t, strings.HasPrefix(ct, "v1:")) assert.Greater(t, len(ct), 10) } | L3: Ciphertext starts with 'v1:' and is base64-encoded | M3: go test -race -v ./pkg/crypto/ -run TestEncrypt | N3: Output format is exactly {version}:{base64} | Two encryptions of same plaintext produce DIFFERENT ciphertexts (random nonce) | O3: Model may forget nonce randomness | may return base64 without version prefix | P3: Done | Q3: feat(crypto): CRY-002 Encrypt method with versioned ciphertext
A4: CRY-003 | B4: Week 3 | C4: Implement Decrypt function | D4: FR-SEC-003 | E4: DDS §5.5 | F4: CRY-002 | G4: Qwen3-14B-Q4_K_M | H4: ~4,000 | I4: You are a Go 1.21 backend engineer. Project: ISP BSS/OSS. Stack: Go 1.21, PostgreSQL 15, Redis 7.2 Sentinel, Asynq. Rules: no global state | all errors wrapped with fmt.Errorf | all DB calls use context.Context | decimal.Decimal for ALL money | never log plaintext PII (aadhaar/pan/mobile) | structured JSON logs via zerolog. Package naming: internal/{module}, pkg/{shared}. FR being implemented: [PASTE ONE FR LINE FROM SRS §2.1] DDS reference: [PASTE RELEVANT SCAFFOLD FROM DDS] | J4: System block + DDS §5.5 Decrypt code pattern. Add function Decrypt(versionedCiphertext string, keyStore KeyStore) (string, error) to pkg/crypto/encryptor.go. Must: split on first ':' to get version | call keyStore.GetKey(version) | base64 decode | AES-GCM decrypt. Return plaintext string or wrapped error. | K4: func TestDecrypt_RoundTrip(t *testing.T) { key := make([]byte, 32) enc := NewAESEncryptor(key, "v1") ct, _ := enc.Encrypt("987654321012") store := &mockKeyStore{"v1": key} plain, err := Decrypt(ct, store) assert.NoError(t, err) assert.Equal(t, "987654321012", plain) } | L4: Decrypted plaintext matches original input | M4: go test -race -v ./pkg/crypto/ -run TestDecrypt | N4: Tampered ciphertext returns error (not panic) | Wrong key version returns error | O4: Model may not handle the 'v1:' prefix split correctly | may panic on malformed input | P4: Done | Q4: feat(crypto): CRY-003 Decrypt with cross-version key store lookup
